try {
    // 예외를 발생시킵니다.
    console.log("여기는 실행해야할 명령들이 있는 곳입니다.");
    console,log("명령을 실핼하다가 애러가 발샐하는 catch로 갑니다")
    //error.error.error();
    throw "내가 만든 에러를 catch가 받습니다. "
    const error = new Error("에러)"

} catch (e) {
    console.log(e.name);
    console.log(e.message);
} finally {
    console.log("에러 처리 끝났습니다. 이 문장은 무조건 실현됩니다. ");
}